<?xml version="1.0" ?>
<!-- =================================================================================== -->
<!-- |    This document was autogenerated by xacro from agv.urdf.xacro                 | -->
<!-- |    EDITING THIS FILE BY HAND IS NOT RECOMMENDED                                 | -->
<!-- =================================================================================== -->
<robot name="agv" xmlns:xacro="http://ros.org/wiki/xacro">
  <!-- DEFINE -->
  <material name="Black">
    <color rgba="0.0 0.0 0.0 1.0"/>
  </material>
  <material name="White">
    <color rgba="1.0 1.0 1.0 1.0"/>
  </material>
  <!-- DEFINE END -->
  <!-- BASE-FOOTPRINT -->
  <!--<link name="base_footprint"/>
  <gazebo reference="base_footprint">
    <material>Gazebo/White</material>
    <gravity>true</gravity>
    <dampingFactor>0.0</dampingFactor>
    <maxVel>100000.0</maxVel>
    <minDepth>0.01</minDepth>
    <mu1>0.0</mu1>
    <mu2>0.0</mu2>
    <fdir1>1 0 0</fdir1>
    <kp>0.0</kp>
    <kd>0.0</kd>
    <selfCollide>false</selfCollide>
    <maxContacts></maxContacts>
    <laserRetro></laserRetro>
  </gazebo>-->
  <!-- AGV_BASE_LINK -->
  <!--<joint name="base_footprint_agv_base_joint" type="fixed">
    <origin xyz="0 0 ${agv_base_height/2+0.13}" rpy="0 0 0" />
    <parent link="base_footprint"/>
    <child link="agv_base_link" />
    <axis xyz="0 0 1" rpy="0 0"/>
    <calibraion rising="0.0" falling="0.0">
    <dynamics damping="10000.0" friction="100000.0"/>
    <limit effort="1000000.0" velocity="100.0"/>
  </joint>
  <gazebo reference="base_footprint_agv_base_joint">
    <stopCfm></stopCfm>
    <stopErp></stopErp>
    <provideFeedback>true</provideFeedback>
    <implicitSpringDamper>true</implicitSpringDamper>
    <fudgeFactor></fudgeFactor>
  </gazebo>-->
  <link name="agv_base_link">
    <visual>
      <origin rpy="0 0 0" xyz="0 0 0"/>
      <geometry>
        <box size="0.7 0.5 0.27"/>
      </geometry>
      <material name="White"/>
    </visual>
    <inertial>
      <mass value="70.0"/>
      <origin rpy="0 0 0" xyz="0 0 0"/>
      <inertia ixx="1.88358333333" ixy="0" ixz="0" iyy="3.28358333333" iyz="0" izz="4.31666666667"/>
    </inertial>
    <!-- base top -->
    <collision>
      <origin rpy="0 0 0" xyz="0 0 0.0535"/>
      <geometry>
        <box size="0.7 0.5 0.108"/>
      </geometry>
    </collision>
    <!-- base bottom -->
    <collision>
      <origin rpy="0 0 0" xyz="0 0 -0.075"/>
      <geometry>
        <box size="0.7 0.5 0.12"/>
      </geometry>
    </collision>
    <!-- four corners -->
    <collision>
      <origin rpy="0 0 0" xyz="0.325 0.225 0.0"/>
      <geometry>
        <box size="0.05 0.05 0.27"/>
      </geometry>
    </collision>
    <collision>
      <origin rpy="0 0 0" xyz="0.325 -0.225 0.0"/>
      <geometry>
        <box size="0.05 0.05 0.27"/>
      </geometry>
    </collision>
    <collision>
      <origin rpy="0 0 0" xyz="-0.325 0.225 0.0"/>
      <geometry>
        <box size="0.05 0.05 0.27"/>
      </geometry>
    </collision>
    <collision>
      <origin rpy="0 0 0" xyz="-0.325 -0.225 0.0"/>
      <geometry>
        <box size="0.05 0.05 0.27"/>
      </geometry>
    </collision>
  </link>
  <gazebo reference="agv_base_link">
    <!--<material>Gazebo/White</material>
    <gravity>true</gravity>
    <dampingFactor>1.0</dampingFactor>
    <maxVel>1000.0</maxVel>
    <minDepth>0.01</minDepth>
    <mu1>0.0</mu1>
    <mu2>0.0</mu2>
    <fdir1>0 0 0</fdir1>
    <kp>0.0</kp>
    <kd>0.0</kd>-->
    <selfCollide>false</selfCollide>
    <!--<maxContacts></maxContacts>
    <laserRetro></laserRetro>-->
  </gazebo>
  <joint name="wheel_front_left_joint" type="continuous">
    <origin rpy="1.570796327 0 0" xyz="0.22 0.22 -0.135"/>
    <parent link="agv_base_link"/>
    <child link="wheel_front_left_link"/>
    <axis rpy="0 0" xyz="0 0 1"/>
    <!-- <calibraion rising="0.0" falling="0.0"> -->
    <dynamics damping="0.0" friction="0.0"/>
    <limit effort="1000000.0" velocity="1000.0"/>
  </joint>
  <!-- <gazebo reference="${name}_joint">
     <stopCfm></stopCfm>
     <stopErp></stopErp>
     <provideFeedback>true</provideFeedback>
     <implicitSpringDamper>true</implicitSpringDamper>
     <fudgeFactor></fudgeFactor> 
   </gazebo> -->
  <link name="wheel_front_left_link" type="wheel">
    <visual>
      <origin rpy="0 0 0" xyz="0 0 0"/>
      <geometry>
        <!-- <mesh filename="package://description/meshes/MPO-500-WHEEL.STL"/> -->
        <cylinder length="0.1" radius="0.12"/>
      </geometry>
      <material name="Black"/>
    </visual>
    <inertial>
      <mass value="2.5"/>
      <origin rpy="0 0 0" xyz="0 0 0"/>
      <inertia ixx="0.0110833333333" ixy="0" ixz="0" iyy="0.0110833333333" iyz="0" izz="0.018"/>
    </inertial>
    <collision>
      <origin rpy="0 0 0" xyz="0 0 0"/>
      <geometry>
        <cylinder length="0.1" radius="0.12"/>
      </geometry>
    </collision>
  </link>
  <gazebo reference="wheel_front_left_link">
    <material>Gazebo/Black</material>
    <gravity>true</gravity>
    <selfCollide>false</selfCollide>
    <maxVel>100.0</maxVel>
    <!--<dampingFactor>1.0</dampingFactor>
    <minDepth>0.01</minDepth>
    <mu1>0.3</mu1>
    <mu2>0.3</mu2>
    <xacro:insert_block name="fdir1"/>
    <kp>100000.0</kp>
    <kd>1.0</kd>
    <maxContacts></maxContacts>
    <laserRetro></laserRetro>-->
  </gazebo>
  <!-- SDF -->
  <gazebo reference="wheel_front_left_link">
    <collision>
      <surface>
        <friction>
          <torsional>
            <coefficient>0.0</coefficient>
          </torsional>
        </friction>
      </surface>
    </collision>
  </gazebo>
  <transmission name="wheel_front_left_joint_trans">
    <type>transmission_interface/SimpleTransmission</type>
    <joint name="wheel_front_left_joint">
      <hardwareInterface>VelocityJointInterface</hardwareInterface>
    </joint>
    <actuator name="wheel_front_left_joint_motor">
      <hardwareInterface>VelocityJointInterface</hardwareInterface>
      <mechanicalReduction>1</mechanicalReduction>
    </actuator>
  </transmission>
  <joint name="wheel_front_right_joint" type="continuous">
    <origin rpy="-1.570796327 0 0" xyz="0.22 -0.22 -0.135"/>
    <parent link="agv_base_link"/>
    <child link="wheel_front_right_link"/>
    <axis rpy="0 0" xyz="0 0 1"/>
    <!-- <calibraion rising="0.0" falling="0.0"> -->
    <dynamics damping="0.0" friction="0.0"/>
    <limit effort="1000000.0" velocity="1000.0"/>
  </joint>
  <!-- <gazebo reference="${name}_joint">
     <stopCfm></stopCfm>
     <stopErp></stopErp>
     <provideFeedback>true</provideFeedback>
     <implicitSpringDamper>true</implicitSpringDamper>
     <fudgeFactor></fudgeFactor> 
   </gazebo> -->
  <link name="wheel_front_right_link" type="wheel">
    <visual>
      <origin rpy="0 0 0" xyz="0 0 0"/>
      <geometry>
        <!-- <mesh filename="package://description/meshes/MPO-500-WHEEL.STL"/> -->
        <cylinder length="0.1" radius="0.12"/>
      </geometry>
      <material name="Black"/>
    </visual>
    <inertial>
      <mass value="2.5"/>
      <origin rpy="0 0 0" xyz="0 0 0"/>
      <inertia ixx="0.0110833333333" ixy="0" ixz="0" iyy="0.0110833333333" iyz="0" izz="0.018"/>
    </inertial>
    <collision>
      <origin rpy="0 0 0" xyz="0 0 0"/>
      <geometry>
        <cylinder length="0.1" radius="0.12"/>
      </geometry>
    </collision>
  </link>
  <gazebo reference="wheel_front_right_link">
    <material>Gazebo/Black</material>
    <gravity>true</gravity>
    <selfCollide>false</selfCollide>
    <maxVel>100.0</maxVel>
    <!--<dampingFactor>1.0</dampingFactor>
    <minDepth>0.01</minDepth>
    <mu1>0.3</mu1>
    <mu2>0.3</mu2>
    <xacro:insert_block name="fdir1"/>
    <kp>100000.0</kp>
    <kd>1.0</kd>
    <maxContacts></maxContacts>
    <laserRetro></laserRetro>-->
  </gazebo>
  <!-- SDF -->
  <gazebo reference="wheel_front_right_link">
    <collision>
      <surface>
        <friction>
          <torsional>
            <coefficient>0.0</coefficient>
          </torsional>
        </friction>
      </surface>
    </collision>
  </gazebo>
  <transmission name="wheel_front_right_joint_trans">
    <type>transmission_interface/SimpleTransmission</type>
    <joint name="wheel_front_right_joint">
      <hardwareInterface>VelocityJointInterface</hardwareInterface>
    </joint>
    <actuator name="wheel_front_right_joint_motor">
      <hardwareInterface>VelocityJointInterface</hardwareInterface>
      <mechanicalReduction>1</mechanicalReduction>
    </actuator>
  </transmission>
  <joint name="wheel_back_left_joint" type="continuous">
    <origin rpy="1.570796327 0 0" xyz="-0.22 0.22 -0.135"/>
    <parent link="agv_base_link"/>
    <child link="wheel_back_left_link"/>
    <axis rpy="0 0" xyz="0 0 1"/>
    <!-- <calibraion rising="0.0" falling="0.0"> -->
    <dynamics damping="0.0" friction="0.0"/>
    <limit effort="1000000.0" velocity="1000.0"/>
  </joint>
  <!-- <gazebo reference="${name}_joint">
     <stopCfm></stopCfm>
     <stopErp></stopErp>
     <provideFeedback>true</provideFeedback>
     <implicitSpringDamper>true</implicitSpringDamper>
     <fudgeFactor></fudgeFactor> 
   </gazebo> -->
  <link name="wheel_back_left_link" type="wheel">
    <visual>
      <origin rpy="0 0 0" xyz="0 0 0"/>
      <geometry>
        <!-- <mesh filename="package://description/meshes/MPO-500-WHEEL.STL"/> -->
        <cylinder length="0.1" radius="0.12"/>
      </geometry>
      <material name="Black"/>
    </visual>
    <inertial>
      <mass value="2.5"/>
      <origin rpy="0 0 0" xyz="0 0 0"/>
      <inertia ixx="0.0110833333333" ixy="0" ixz="0" iyy="0.0110833333333" iyz="0" izz="0.018"/>
    </inertial>
    <collision>
      <origin rpy="0 0 0" xyz="0 0 0"/>
      <geometry>
        <cylinder length="0.1" radius="0.12"/>
      </geometry>
    </collision>
  </link>
  <gazebo reference="wheel_back_left_link">
    <material>Gazebo/Black</material>
    <gravity>true</gravity>
    <selfCollide>false</selfCollide>
    <maxVel>100.0</maxVel>
    <!--<dampingFactor>1.0</dampingFactor>
    <minDepth>0.01</minDepth>
    <mu1>0.3</mu1>
    <mu2>0.3</mu2>
    <xacro:insert_block name="fdir1"/>
    <kp>100000.0</kp>
    <kd>1.0</kd>
    <maxContacts></maxContacts>
    <laserRetro></laserRetro>-->
  </gazebo>
  <!-- SDF -->
  <gazebo reference="wheel_back_left_link">
    <collision>
      <surface>
        <friction>
          <torsional>
            <coefficient>0.0</coefficient>
          </torsional>
        </friction>
      </surface>
    </collision>
  </gazebo>
  <transmission name="wheel_back_left_joint_trans">
    <type>transmission_interface/SimpleTransmission</type>
    <joint name="wheel_back_left_joint">
      <hardwareInterface>VelocityJointInterface</hardwareInterface>
    </joint>
    <actuator name="wheel_back_left_joint_motor">
      <hardwareInterface>VelocityJointInterface</hardwareInterface>
      <mechanicalReduction>1</mechanicalReduction>
    </actuator>
  </transmission>
  <joint name="wheel_back_right_joint" type="continuous">
    <origin rpy="-1.570796327  0 0" xyz="-0.22 -0.22 -0.135"/>
    <parent link="agv_base_link"/>
    <child link="wheel_back_right_link"/>
    <axis rpy="0 0" xyz="0 0 1"/>
    <!-- <calibraion rising="0.0" falling="0.0"> -->
    <dynamics damping="0.0" friction="0.0"/>
    <limit effort="1000000.0" velocity="1000.0"/>
  </joint>
  <!-- <gazebo reference="${name}_joint">
     <stopCfm></stopCfm>
     <stopErp></stopErp>
     <provideFeedback>true</provideFeedback>
     <implicitSpringDamper>true</implicitSpringDamper>
     <fudgeFactor></fudgeFactor> 
   </gazebo> -->
  <link name="wheel_back_right_link" type="wheel">
    <visual>
      <origin rpy="0 0 0" xyz="0 0 0"/>
      <geometry>
        <!-- <mesh filename="package://description/meshes/MPO-500-WHEEL.STL"/> -->
        <cylinder length="0.1" radius="0.12"/>
      </geometry>
      <material name="Black"/>
    </visual>
    <inertial>
      <mass value="2.5"/>
      <origin rpy="0 0 0" xyz="0 0 0"/>
      <inertia ixx="0.0110833333333" ixy="0" ixz="0" iyy="0.0110833333333" iyz="0" izz="0.018"/>
    </inertial>
    <collision>
      <origin rpy="0 0 0" xyz="0 0 0"/>
      <geometry>
        <cylinder length="0.1" radius="0.12"/>
      </geometry>
    </collision>
  </link>
  <gazebo reference="wheel_back_right_link">
    <material>Gazebo/Black</material>
    <gravity>true</gravity>
    <selfCollide>false</selfCollide>
    <maxVel>100.0</maxVel>
    <!--<dampingFactor>1.0</dampingFactor>
    <minDepth>0.01</minDepth>
    <mu1>0.3</mu1>
    <mu2>0.3</mu2>
    <xacro:insert_block name="fdir1"/>
    <kp>100000.0</kp>
    <kd>1.0</kd>
    <maxContacts></maxContacts>
    <laserRetro></laserRetro>-->
  </gazebo>
  <!-- SDF -->
  <gazebo reference="wheel_back_right_link">
    <collision>
      <surface>
        <friction>
          <torsional>
            <coefficient>0.0</coefficient>
          </torsional>
        </friction>
      </surface>
    </collision>
  </gazebo>
  <transmission name="wheel_back_right_joint_trans">
    <type>transmission_interface/SimpleTransmission</type>
    <joint name="wheel_back_right_joint">
      <hardwareInterface>VelocityJointInterface</hardwareInterface>
    </joint>
    <actuator name="wheel_back_right_joint_motor">
      <hardwareInterface>VelocityJointInterface</hardwareInterface>
      <mechanicalReduction>1</mechanicalReduction>
    </actuator>
  </transmission>
  <!-- Lidar 
  <xacro:include filename="$(find launcher)/urdf/lidar/lidar.urdf.xacro" />
  
  <xacro:lidar_block name="agvlidar_top" parent="agv_base_link">
    <origin xyz="0.19 0.0 ${agv_base_height/2-0.025}" rpy="0 0 0" />
  </xacro:lidar_block>-->
  <!-- <xacro:lidar_block name="agvlidar_bot" parent="agv_base_link">
    <origin xyz="-0.19 0.0 -0.005" rpy="0 0 0" />
  </xacro:lidar_block> -->
  <!-- Camera 
  <xacro:include filename="$(find launcher)/urdf/camera/camera.urdf.xacro" />
  
  <xacro:camera_block name="agvcam_front" parent="agv_base_link">
    <origin xyz="0.35 0.0 0.07" rpy="0 0 0" />
  </xacro:camera_block>
  <xacro:camera_block name="agvcam_back" parent="agv_base_link">
    <origin xyz="-0.35 0.0 0.07" rpy="0 0 ${M_PI}" />
  </xacro:camera_block>
  <xacro:camera_block name="agvcam_left" parent="agv_base_link">
    <origin xyz="0.0 -0.25 0.07" rpy="0 0 ${-M_PI_2}" />
  </xacro:camera_block>
  <xacro:camera_block name="agvcam_right" parent="agv_base_link">
    <origin xyz="0.0 0.25 0.07" rpy="0 0 ${M_PI_2}" />
  </xacro:camera_block>-->
  <gazebo>
    <plugin filename="libgazebo_ros_control.so" name="gazebo_ros_control">
      <robotNamespace>agv</robotNamespace>
      <controlPeriod>0.001</controlPeriod>
      <robotParam>/robot_description</robotParam>
      <robotSimType>gazebo_ros_control/DefaultRobotHWSim</robotSimType>
    </plugin>
  </gazebo>
</robot>
